  0%|                                                   | 0/491 [00:00<?, ?it/s]Traceback (most recent call last):
  File "/home/ViVidBot/Valley/valley/train/train.py", line 220, in <module>
    train(args)
  File "/home/ViVidBot/Valley/valley/train/train.py", line 208, in train
    trainer.train()
  File "/opt/conda/lib/python3.10/site-packages/transformers/trainer.py", line 1885, in train
    return inner_training_loop(
  File "/opt/conda/lib/python3.10/site-packages/transformers/trainer.py", line 2178, in _inner_training_loop
    for step, inputs in enumerate(epoch_iterator):
  File "/opt/conda/lib/python3.10/site-packages/accelerate/data_loader.py", line 454, in __iter__
    current_batch = next(dataloader_iter)
  File "/opt/conda/lib/python3.10/site-packages/torch/utils/data/dataloader.py", line 631, in __next__
    data = self._next_data()
  File "/opt/conda/lib/python3.10/site-packages/torch/utils/data/dataloader.py", line 675, in _next_data
    data = self._dataset_fetcher.fetch(index)  # may raise StopIteration
  File "/opt/conda/lib/python3.10/site-packages/torch/utils/data/_utils/fetch.py", line 54, in fetch
    return self.collate_fn(data)
  File "/home/ViVidBot/Valley/valley/data/dataset.py", line 177, in __call__
    input_ids = torch.nn.utils.rnn.pad_sequence(
  File "/opt/conda/lib/python3.10/site-packages/torch/nn/utils/rnn.py", line 399, in pad_sequence
    return torch._C._nn.pad_sequence(sequences, batch_first, padding_value)
RuntimeError: received an empty list of sequences
list index out of range
8nLfpaxqPf0.4
list index out of range
-0pGuQoaq1w.36
list index out of range
zt3fN6KigV0.9
list index out of range
u7JJKgXK48Y.20
list index out of range
DhXPI9QxyIw.59
list index out of range
F_DhTNMy6Lo.21
list index out of range
aw4dQ8V30lo.1
list index out of range
lqREd_flHjc.4