  0%|                                                   | 0/491 [00:00<?, ?it/s]Traceback (most recent call last):
  File "/home/ViVidBot/Valley/valley/train/train.py", line 220, in <module>
    train(args)
  File "/home/ViVidBot/Valley/valley/train/train.py", line 208, in train
    trainer.train()
  File "/opt/conda/lib/python3.10/site-packages/transformers/trainer.py", line 1885, in train
    return inner_training_loop(
  File "/opt/conda/lib/python3.10/site-packages/transformers/trainer.py", line 2178, in _inner_training_loop
    for step, inputs in enumerate(epoch_iterator):
  File "/opt/conda/lib/python3.10/site-packages/accelerate/data_loader.py", line 454, in __iter__
    current_batch = next(dataloader_iter)
  File "/opt/conda/lib/python3.10/site-packages/torch/utils/data/dataloader.py", line 631, in __next__
    data = self._next_data()
  File "/opt/conda/lib/python3.10/site-packages/torch/utils/data/dataloader.py", line 675, in _next_data
    data = self._dataset_fetcher.fetch(index)  # may raise StopIteration
  File "/opt/conda/lib/python3.10/site-packages/torch/utils/data/_utils/fetch.py", line 54, in fetch
    return self.collate_fn(data)
  File "/home/ViVidBot/Valley/valley/data/dataset.py", line 178, in __call__
    input_ids = torch.nn.utils.rnn.pad_sequence(
  File "/opt/conda/lib/python3.10/site-packages/torch/nn/utils/rnn.py", line 399, in pad_sequence
    return torch._C._nn.pad_sequence(sequences, batch_first, padding_value)
RuntimeError: received an empty list of sequences
uHyO2ctjaBI.14.mp4
list index out of range
uHyO2ctjaBI.14
tVLR5prgm10.23.mp4
list index out of range
tVLR5prgm10.23
eNyPlOslt9U.25.mp4
list index out of range
eNyPlOslt9U.25
4FMdbwDdHlw.28.mp4
list index out of range
4FMdbwDdHlw.28
7SthDio8vQY.21.mp4
list index out of range
7SthDio8vQY.21
UFNMaJq0kUo.4.mp4
list index out of range
UFNMaJq0kUo.4
MD7y_ZHKZO4.0.mp4
list index out of range
MD7y_ZHKZO4.0
Gf4-qCdtRWk.3.mp4
list index out of range
Gf4-qCdtRWk.3